#VRML_SIM R2023b utf8

EXTERNPROTO "https://raw.githubusercontent.com/cyberbotics/webots/R2023b/projects/objects/backgrounds/protos/TexturedBackground.proto"
EXTERNPROTO "https://raw.githubusercontent.com/cyberbotics/webots/R2023b/projects/objects/backgrounds/protos/TexturedBackgroundLight.proto"
EXTERNPROTO "https://raw.githubusercontent.com/cyberbotics/webots/R2023b/projects/objects/floors/protos/Floor.proto"
EXTERNPROTO "https://raw.githubusercontent.com/cyberbotics/webots/R2023b/projects/objects/apartment_structure/protos/Wall.proto"
EXTERNPROTO "https://raw.githubusercontent.com/cyberbotics/webots/R2023b/projects/objects/lights/protos/FloorLight.proto"

WorldInfo {
}
Viewpoint {
  orientation -0.42233421110497504 0.0049203249137706115 0.906426833524406 3.1204798248353365
  position 3.576040313755915 -0.13007890842033318 3.925236276134068
}
TexturedBackground {
}
TexturedBackgroundLight {
}

Viewpoint {
  orientation -0.33185733874619844 -0.09874274160469809 0.9381474178937331 3.686018050088086
  position 1.700313773507203 1.0549607538959629 1.4846240848267684
  follow "my_robot"
}

Floor {
  size 3 3
}
Wall {
  translation -1.5 0 0
  name "boundary1"
  size 0.05 3 0.2
}
Wall {
  translation 1.5 0 0
  name "boundary2"
  size 0.05 3 0.2
}
Wall {
  translation 0 -1.5 0
  rotation 0 0 1 1.5707996938995747
  name "boundary3"
  size 0.05 3 0.2
}
Wall {
  translation 0 1.5 0
  rotation 0 0 1 1.5707996938995747
  name "boundary4"
  size 0.05 3 0.2
}
Solid {
  translation 0.383277 -0.500903 9.28146e-14
  children [
    DEF stripWall Shape {
      appearance PBRAppearance {
        roughness 0.5
        metalness 0
      }
      geometry Box {
        size 0.25 1 0.3
      }
    }
  ]
  boundingObject USE stripWall
}
Solid {
  translation 0.877384 0.997393 -2.22045e-15
  children [
    USE stripWall
  ]
  name "solid(1)"
  boundingObject USE stripWall
}
Solid {
  translation -0.238026 -0.874231 -7.10543e-15
  rotation 0 0 1 1.5707996938995747
  children [
    USE stripWall
  ]
  name "solid(2)"
  boundingObject USE stripWall
}
Solid {
  translation -0.62 0.5 -1.77636e-15
  children [
    USE stripWall
  ]
  name "solid(3)"
  boundingObject USE stripWall
}
Solid {
  translation -0.87 0.875 -1.33227e-14
  children [
    DEF block_wall Shape {
      appearance PBRAppearance {
        roughness 0.5
        metalness 0
      }
      geometry Box {
        size 0.25 0.25 0.3
      }
    }
  ]
  name "solid(4)"
  boundingObject USE block_wall
}
Solid {
  translation 0.632572 -0.127299 0
  children [
    USE block_wall
  ]
  name "solid(5)"
  boundingObject USE block_wall
}
Robot {
  children [
    FloorLight {
      bulbColor 1 0 0
      scale 0.2
      pointLightColor 1 0 0
      pointLightIntensity 0.4
    }
    TouchSensor {
      name "bump sensor"
      boundingObject DEF flag_cylinder Cylinder {
        height 0.3
        radius 0.02
      }
    }
  ]
  name "flag"
  boundingObject USE flag_cylinder
}
Robot {
  translation 0.5 0.5 0
  children [
    HingeJoint {
      jointParameters HingeJointParameters {
        axis 0 1 0
        anchor 0 0 0.025
      }
      device [
        RotationalMotor {
          name "left wheel motor"
        }
      ]
      endPoint Solid {
        translation 0 0.045 0.025
        children [
          DEF WHEEL1 Transform {
            rotation 1 0 0 1.5707996938995747
            children [
              Shape {
                appearance PBRAppearance {
                  baseColor 1 0 0
                  roughness 1
                  metalness 0
                }
                geometry Cylinder {
                  height 0.01
                  radius 0.025
                }
              }
            ]
          }
        ]
        name "left wheel"
        boundingObject USE WHEEL1
        physics Physics {
        }
      }
    }
    HingeJoint {
      jointParameters HingeJointParameters {
        axis 0 1 0
        anchor 0 0 0.025
      }
      device [
        RotationalMotor {
          name "right wheel motor"
        }
      ]
      endPoint Solid {
        translation 0 -0.045 0.025
        children [
          USE WHEEL1
        ]
        name "right wheel"
        boundingObject USE WHEEL1
        physics Physics {
        }
      }
    }
    Transform {
      translation 0 0 0.0415
      children [
        Shape {
          appearance PBRAppearance {
            baseColor 0 0 1
            roughness 1
            metalness 0
          }
          geometry DEF BODY1 Cylinder {
            height 0.08
            radius 0.045
          }
        }
      ]
    }
    DistanceSensor {
      translation 0.042 0.02 0.063
      rotation 0 0 1 0.5236003061004253
      children [
        DEF SENSOR1 Transform {
          rotation 0 1 0 1.5708
          children [
            Shape {
              appearance PBRAppearance {
                baseColor 1 1 0
                roughness 1
                metalness 0
              }
              geometry Cylinder {
                height 0.004
                radius 0.008
              }
            }
          ]
        }
      ]
      name "ds0"
      lookupTable [
        0 1020 0
        0.05 1020 0
        0.15 0 0
      ]
      numberOfRays 2
      aperture 1
    }
    DistanceSensor {
      translation 0.042 -0.02 0.063
      rotation 0 0 1 -0.5235996938995747
      children [
        USE SENSOR1
      ]
      name "ds1"
      lookupTable [
        0 1020 0
        0.05 1020 0
        0.15 0 0
      ]
      numberOfRays 2
      aperture 1
    }
    TouchSensor {
      translation 0.042 0 0.03
      children [
        DEF SENSOR_SHAPE Shape {
          appearance PBRAppearance {
            baseColor 0.8 0.8 0.8
            transparency 0.5
            roughness 1
            metalness 0
          }
          geometry Box {
            size 0.25 0.1 0.01
          }
        }
      ]
      name "touch"
      boundingObject USE SENSOR_SHAPE
      physics Physics {
      }
      type "bumper"
      lookupTable []
    }
  ]
  boundingObject Transform {
    translation 0 0 0.0415
    children [
      USE BODY1
    ]
  }
  physics Physics {
  }
  controller "<extern>"
  name "my_robot"
}
Robot {
  translation 0 0.2 0
  children [
    HingeJoint {
      jointParameters HingeJointParameters {
        axis 0 1 0
        anchor 0 0 0.025
      }
      device [
        RotationalMotor {
          name "left wheel motor"
        }
      ]
      endPoint Solid {
        translation 0 0.045 0.025
        children [
          DEF WHEEL2 Transform {
            rotation 1 0 0 1.5707996938995747
            children [
              Shape {
                appearance PBRAppearance {
                  baseColor 1 0 0
                  roughness 1
                  metalness 0
                }
                geometry Cylinder {
                  height 0.01
                  radius 0.025
                }
              }
            ]
          }
        ]
        name "left wheel"
        boundingObject USE WHEEL2
        physics Physics {
        }
      }
    }
    HingeJoint {
      jointParameters HingeJointParameters {
        axis 0 1 0
        anchor 0 0 0.025
      }
      device [
        RotationalMotor {
          name "right wheel motor"
        }
      ]
      endPoint Solid {
        translation 0 -0.045 0.025
        children [
          USE WHEEL2
        ]
        name "right wheel"
        boundingObject USE WHEEL2
        physics Physics {
        }
      }
    }
    Transform {
      translation 0 0 0.0415
      children [
        Shape {
          appearance PBRAppearance {
            baseColor 0 1 0
            roughness 1
            metalness 0
          }
          geometry DEF BODY2 Cylinder {
            height 0.08
            radius 0.045
          }
        }
      ]
    }
    DistanceSensor {
      translation 0.042 0.02 0.063
      rotation 0 0 1 0.5236003061004253
      children [
        DEF SENSOR2 Transform {
          rotation 0 1 0 1.5708
          children [
            Shape {
              appearance PBRAppearance {
                baseColor 1 1 0
                roughness 1
                metalness 0
              }
              geometry Cylinder {
                height 0.004
                radius 0.008
              }
            }
          ]
        }
      ]
      name "ds2"
      lookupTable [
        0 1020 0
        0.05 1020 0
        0.15 0 0
      ]
      numberOfRays 2
      aperture 1
    }
    DistanceSensor {
      translation 0.042 -0.02 0.063
      rotation 0 0 1 -0.5235996938995747
      children [
        USE SENSOR2
      ]
      name "ds3"
      lookupTable [
        0 1020 0
        0.05 1020 0
        0.15 0 0
      ]
      numberOfRays 2
      aperture 1
    }
  ]
  boundingObject Transform {
    translation 0 0 0.0415
    children [
      USE BODY2
    ]
  }
  physics Physics {
  }
  controller "<extern>"
  name "my_robot_2"
}